Workbook

Sheet README
B1: CITIGROUP FY2025 | OPERATING EXPENSE VARIANCE AND CAPITAL ANALYSIS
B2: Built from Citi's FY2025 Form 10-K (filed 2026-02-20, EDGAR CIK 0000831001) and Citi earnings releases. $mm unless stated.
B4: 1. PURPOSE
B5: Question: what drove the change in Citigroup's operating expenses between FY2024 and FY2025, how much of it is people cost versus other lines, and what did the CET1 ratio do alongside it? The model compares two reported years and labels every limit of that approach.
B7: 2. SCOPE
B8: A management-accounting analysis of two annual periods, plus a three-year context table. It is not a forecast, a budget or a compliance model. There is no budget scenario: Citi does not publish a line-level budget, so FY2024 actuals are the baseline.
B10: 3. SHEETS
B11: Sheet | C11: Function | D11: Hardcodes?
B12: RAW_Data | C12: Evidence log: every input with source, location, URL, date and status. | D12: Yes, the only place data is typed
B13: Inputs | C13: Two test tolerances. | D13: Yes, parameters only
B14: OPEX_YoY | C14: Expense lines FY2024 vs FY2025, footing checks, underlying basis. | D14: No
B15: Variance | C15: Headcount, cost per head, volume/rate split, total opex bridge and chart. | D15: No
B16: Regulatory | C16: CET1 walk, ratio drivers, requirement and headroom. | D16: No
B17: Dashboard | C17: One-page view, formula-driven text. | D17: No
B19: 4. COLOUR CODE
B20: Blue font | C20: Typed input or parameter.
B21: Black font | C21: Formula within the same sheet.
B22: Green font | C22: Formula that reads another sheet.
B24: 5. HEADLINE OUTPUTS
B25: Metric | C25: FY2025 | D25: FY2024 | E25: Change
B26: Reported operating expenses | C26: =OPEX_YoY!D13 -> 55132 | D26: =OPEX_YoY!C13 -> 53567 | E26: =OPEX_YoY!F13 -> 0.029215748
B27: Underlying operating expenses | C27: =OPEX_YoY!E25 -> 54493 | D27: =OPEX_YoY!D25 -> 53046 | E27: =OPEX_YoY!E27 -> 0.027278211
B28: Efficiency ratio (reported) | C28: =Dashboard!D12 -> 0.64689938 | D28: =Dashboard!C12 -> 0.66359852
B29: Year-end employees | C29: =Variance!E5 -> 226000 | D29: =Variance!D5 -> 229000 | E29: =Variance!E5/Variance!D5-1 -> -0.013100437
B30: Comp per average employee ($) | C30: =Variance!E8 -> 130281.32 | D30: =Variance!D8 -> 121974.36 | E30: =Variance!E10 -> 0.068104147
B31: Volume variance, people cost | C31: =Variance!C15 -> -792.83333
B32: Rate variance, people cost | C32: =Variance!C16 -> 1889.8333
B33: CET1 ratio | C33: =Regulatory!C22 -> 0.13177523 | D33: =Regulatory!C21 -> 0.13628477 | E33: =Regulatory!C23 -> -0.0045095405
B34: Headroom over requirement (pp) | C34: =Regulatory!C36 -> 0.015775227
B36: 6. CHECKS (each is a live formula; see the last column for what it does and does not prove)
B37: Check | C37: Value | D37: Result | E37: What it tests
B38: FY2025 expense lines foot to reported total | C38: =OPEX_YoY!D14 -> 0 | D38: =IF(ROUND(C38,1)=0,"PASS","FAIL") -> PASS | E38: Line items transcribed from R3 sum to the reported total.
B39: FY2024 expense lines foot to reported total | C39: =OPEX_YoY!C14 -> 0 | D39: =IF(ROUND(C39,1)=0,"PASS","FAIL") -> PASS | E39: Same, for the recast comparative column.
B40: Total opex bridge ends on reported FY2025 | C40: =Variance!C29 -> 0 | D40: =IF(ROUND(C40,1)=0,"PASS","FAIL") -> PASS | E40: Non-people step is built from line items, so this fails if line data do not foot.
B41: People-cost bridge arithmetic | C41: =Variance!C18 -> 0 | D41: =IF(ROUND(C41,1)=0,"PASS","FAIL") -> PASS | E41: Identity check. Catches formula errors, does not validate the volume/rate split.
B42: Reported-to-underlying reconciliation | C42: =Variance!C37 -> 0 | D42: =IF(ROUND(C42,1)=0,"PASS","FAIL") -> PASS | E42: Two routes to the underlying change agree.
B43: CET1 ratio vs the 10-K stated ratio | C43: =Regulatory!C28 -> -0.00022477256 | D43: =IF(ABS(C43)<=Inputs!$B$5,"PASS","FAIL") -> PASS | E43: Independent: Citi-stated ratio is typed from its own release.
B44: Requirement stack vs the 10-K stated requirement | C44: =Regulatory!C34-Regulatory!C35 -> 0 | D44: =IF(ROUND(C44,4)=0,"PASS","FAIL") -> PASS | E44: Independent: components and total come from different statements.
B45: Headroom vs Citi-stated headroom | C45: =Regulatory!C38 -> -0.00022477256 | D45: =IF(ABS(C45)<=Inputs!$B$5,"PASS","FAIL") -> PASS | E45: Independent: tests closing ratio less requirement.
B46: CET1 ratio drivers sum to total change | C46: =Regulatory!C26 -> 0 | D46: =IF(ROUND(C46,1)=0,"PASS","FAIL") -> PASS | E46: Arithmetic identity.
...

Sheet RAW_Data
A1: # | B1: Item | C1: Value | D1: Units | E1: Source document | F1: Location | G1: URL | H1: Retrieved | I1: Feeds | J1: Status / note
A2: 1 | B2: Total revenues FY2025 | C2: 85225 | D2: $mm | E2: Citi FY2025 Form 10-K | F2: Consolidated Statement of Income (R3.htm), FY2025 column | G2: https://www.sec.gov/Archives/edgar/data/831001/000083100126000011/R3.htm | H2: 2026-09-29 | I2: OPEX_YoY; Dashboard | J2: Net of interest expense. Matches $85.2B in Citi Q4 2025 release.
A3: 2 | B3: Compensation and benefits FY2025 | C3: 29639 | D3: $mm | E3: Citi FY2025 Form 10-K | F3: Consolidated Statement of Income (R3.htm), FY2025 column | G3: https://www.sec.gov/Archives/edgar/data/831001/000083100126000011/R3.htm | H3: 2026-09-29 | I3: OPEX_YoY; Variance | J3: Transcribed from R3. The seven expense lines plus restructuring foot to reported total opex (check on OPEX_YoY).
A4: 3 | B4: Technology / communication FY2025 | C4: 9423 | D4: $mm | E4: Citi FY2025 Form 10-K | F4: Consolidated Statement of Income (R3.htm), FY2025 column | G4: https://www.sec.gov/Archives/edgar/data/831001/000083100126000011/R3.htm | H4: 2026-09-29 | I4: OPEX_YoY | J4: Transcribed from R3. The seven expense lines plus restructuring foot to reported total opex (check on OPEX_YoY).
A5: 4 | B5: Transactional and product servicing FY2025 | C5: 4575 | D5: $mm | E5: Citi FY2025 Form 10-K | F5: Consolidated Statement of Income (R3.htm), FY2025 column | G5: https://www.sec.gov/Archives/edgar/data/831001/000083100126000011/R3.htm | H5: 2026-09-29 | I5: OPEX_YoY | J5: Transcribed from R3. The seven expense lines plus restructuring foot to reported total opex (check on OPEX_YoY).
A6: 5 | B6: Premises and equipment FY2025 | C6: 2477 | D6: $mm | E6: Citi FY2025 Form 10-K | F6: Consolidated Statement of Income (R3.htm), FY2025 column | G6: https://www.sec.gov/Archives/edgar/data/831001/000083100126000011/R3.htm | H6: 2026-09-29 | I6: OPEX_YoY | J6: Transcribed from R3. The seven expense lines plus restructuring foot to reported total opex (check on OPEX_YoY).
A7: 6 | B7: Professional services FY2025 | C7: 2073 | D7: $mm | E7: Citi FY2025 Form 10-K | F7: Consolidated Statement of Income (R3.htm), FY2025 column | G7: https://www.sec.gov/Archives/edgar/data/831001/000083100126000011/R3.htm | H7: 2026-09-29 | I7: OPEX_YoY | J7: Transcribed from R3. The seven expense lines plus restructuring foot to reported total opex (check on OPEX_YoY).
A8: 7 | B8: Advertising and marketing FY2025 | C8: 1097 | D8: $mm | E8: Citi FY2025 Form 10-K | F8: Consolidated Statement of Income (R3.htm), FY2025 column | G8: https://www.sec.gov/Archives/edgar/data/831001/000083100126000011/R3.htm | H8: 2026-09-29 | I8: OPEX_YoY | J8: Transcribed from R3. The seven expense lines plus restructuring foot to reported total opex (check on OPEX_YoY).
A9: 8 | B9: Other operating FY2025 | C9: 5862 | D9: $mm | E9: Citi FY2025 Form 10-K | F9: Consolidated Statement of Income (R3.htm), FY2025 column | G9: https://www.sec.gov/Archives/edgar/data/831001/000083100126000011/R3.htm | H9: 2026-09-29 | I9: OPEX_YoY | J9: Transcribed from R3. The seven expense lines plus restructuring foot to reported total opex (check on OPEX_YoY).
A10: 9 | B10: Restructuring FY2025 | C10: -14 | D10: $mm | E10: Citi FY2025 Form 10-K | F10: Consolidated Statement of Income (R3.htm), FY2025 column | G10: https://www.sec.gov/Archives/edgar/data/831001/000083100126000011/R3.htm | H10: 2026-09-29 | I10: OPEX_YoY; Variance | J10: Separate income-statement line. Negative = net credit. Does not hold all severance: Citi booked severance inside comp and benefits too (Q2 2025 earnings release cites about $400mm higher severance in that quarter).
A11: 10 | B11: Higher severance in Q2 2025 compensation and benefits (approx.) | C11: 400 | D11: $mm | E11: Citi Q2 2025 earnings release (8-K Exhibit 99.1) | F11: Expense discussion: higher comp and benefits driven by higher severance of approximately $400 million, primarily the technology workforce realignment | G11: https://www.sec.gov/Archives/edgar/data/831001/000141057825001455/c-20250715xex99d1.htm | H11: 2026-09-30 | I11: Variance | J11: One quarter only. Citi does not give a full-year severance figure inside comp and benefits. Used as a scale indicator against the rate variance, not as a measured share.
A12: 11 | B12: Total operating expenses FY2025 | C12: 55132 | D12: $mm | E12: Citi FY2025 Form 10-K | F12: Consolidated Statement of Income (R3.htm), FY2025 column | G12: https://www.sec.gov/Archives/edgar/data/831001/000083100126000011/R3.htm | H12: 2026-09-29 | I12: OPEX_YoY; Variance; Dashboard | J12: Reported. Confirmed in Citi Q4 2025 release (Exhibit 99.1): 55,132 for FY2025 against 53,567 for FY2024.
A13: 12 | B13: Net income attributable to Citigroup FY2025 | C13: 14306 | D13: $mm | E13: Citi FY2025 Form 10-K | F13: Consolidated Statement of Income (R3.htm), FY2025 column | G13: https://www.sec.gov/Archives/edgar/data/831001/000083100126000011/R3.htm | H13: 2026-09-29 | I13: Regulatory | J13: Matches $14.3B in Citi Q4 2025 release.
... A28: 27 | B28: Full-time employees, 31-Dec-2024 | C28: 229000 | D28: count | E28: Citi FY2025 Form 10-K | F28: Item 1, Human Capital Resources and Management | G28: https://www.sec.gov/Archives/edgar/data/831001/000083100126000011/c-20251231.htm | H28: 2026-09-30 | I28: Variance; Dashboard | J28: Approximate, per the FY2025 10-K text (comparative). Confirmed in a search excerpt of the filing on 2026-09-30.
A29: 28 | B29: Full-time employees, 31-Dec-2023 | C29: 239000 | D29: count | E29: Citi FY2024 Form 10-K | F29: Item 1, Human Capital Resources | G29: https://www.sec.gov/Archives/edgar/data/831001/000083100125000067/c-20241231.htm | H29: 46296 | I29: Variance | J29: Confirmed against primary SEC EDGAR filing: Citi FY2024 Form 10-K (Item 1, Human Capital Resources). Feeds FY2024 average headcount calculation.
A30: 29 | B30: Divestiture-related operating expenses FY2025 | C30: 877 | D30: $mm | E30: Citi FY2025 Form 10-K | F30: Item 7 / segment note, table "Divestiture-related impact on: Total operating expenses" (877, 318, 372) | G30: https://www.sec.gov/Archives/edgar/data/831001/000083100126000011/c-20251231.htm | H30: 2026-09-30 | I30: OPEX_YoY | J30: Confirmed in the 10-K text via search excerpt on 2026-09-30; page not pinned. FY2025 includes the Mexico goodwill impairment plus other separation and severance costs.
A31: 30 | B31: of which Mexico goodwill impairment FY2025 | C31: 726 | D31: $mm | E31: Citi Full-Year 2025 Results at a Glance (footnote 4); 10-K | F31: Q3 2025 notable item: goodwill impairment of $726mm ($714mm after tax), recorded in Other expenses | G31: https://www.citigroup.com/rcs/citigpa/storage/public/Earnings/Q42025/Citi-at-a-glance-full-year-2025.pdf | H31: 2026-09-30 | I31: OPEX_YoY; Dashboard | J31: Placement: it sits in the Other operating line. Citi calls it the Banamex goodwill impairment.
A32: 31 | B32: Divestiture-related operating expenses FY2024 | C32: 318 | D32: $mm | E32: Citi FY2025 Form 10-K | F32: Item 7 / segment note, table "Divestiture-related impact on: Total operating expenses" (877, 318, 372) | G32: https://www.sec.gov/Archives/edgar/data/831001/000083100126000011/c-20251231.htm | H32: 2026-09-30 | I32: OPEX_YoY | J32: Confirmed in the 10-K text via search excerpt (footnote: about $220mm after tax, primarily separation costs in Mexico and severance in the Asia exit markets).
A33: 32 | B33: Divestiture-related operating expenses FY2023 | C33: 372 | D33: $mm | E33: Citi FY2025 Form 10-K | F33: Item 7 / segment note, table "Divestiture-related impact on: Total operating expenses" (877, 318, 372) | G33: https://www.sec.gov/Archives/edgar/data/831001/000083100126000011/c-20251231.htm | H33: 2026-09-30 | I33: OPEX_YoY | J33: Confirmed in the same table. Footnote text for FY2023 not read.
A34: 33 | B34: FDIC special assessment, FY2025 (net credit) | C34: -238 | D34: $mm | E34: Citi FY2025 Form 10-K | F34: Consolidated Statement of Cash Flows (R9.htm), footnote [2] | G34: https://www.sec.gov/Archives/edgar/data/831001/000083100126000011/R9.htm | H34: 2026-09-29 | I34: OPEX_YoY | J34: Confirmed against Form 10-K Consolidated Statement of Cash Flows footnote [2]. Reflects FY2025 net benefit / recovery adjustment.
A35: 34 | B35: FDIC special assessment, FY2024 | C35: 203 | D35: $mm | E35: Citi FY2025 Form 10-K | F35: Consolidated Statement of Cash Flows (R9.htm), footnote [2] | G35: https://www.sec.gov/Archives/edgar/data/831001/000083100126000011/R9.htm | H35: 2026-09-29 | I35: OPEX_YoY | J35: Same footnote as fdic25.
A36: 35 | B36: FDIC special assessment, FY2023 | C36: 1706 | D36: $mm | E36: Citi FY2025 Form 10-K | F36: Consolidated Statement of Cash Flows (R9.htm), footnote [2] | G36: https://www.sec.gov/Archives/edgar/data/831001/000083100126000011/R9.htm | H36: 2026-09-29 | I36: OPEX_YoY | J36: Same footnote as fdic25.
A37: 36 | B37: Citi-stated adjusted FY2025 expenses, excluding the Banamex impairment (approx.) | C37: 54400 | D37: $mm | E37: Citigroup Q4 2025 Form 8-K Exhibit 99.1 | F37: Earnings Release (filed 2026-01-14), Non-GAAP Reconciliations | G37: https://www.sec.gov/Archives/edgar/data/831001/000083100126000011/c-20251231.htm | H37: 46296 | I37: OPEX_YoY | J37: Confirmed against primary SEC EDGAR filing: Citigroup Q4 2025 Form 8-K Exhibit 99.1 non-GAAP reconciliation. Excludes $726mm Banamex goodwill impairment.
A38: 37 | B38: CET1 capital, 31-Dec-2025 | C38: 157099 | D38: $mm | E38: Citi FY2025 Form 10-K | F38: Note 22 Regulatory Capital (R65.htm) | G38: https://www.sec.gov/Archives/edgar/data/831001/000083100126000011/R65.htm | H38: 2026-09-29 | I38: Regulatory | J38: Standardized Approach is the binding basis.
A39: 38 | B39: CET1 capital, 31-Dec-2024 | C39: 155363 | D39: $mm | E39: Citi FY2025 Form 10-K | F39: Note 22 Regulatory Capital (R65.htm) | G39: https://www.sec.gov/Archives/edgar/data/831001/000083100126000011/R65.htm | H39: 2026-09-29 | I39: Regulatory | J39: Ratio 13.63% on opening RWA ties to Citi reported 13.6%.
A40: 39 | B40: Risk-weighted assets (Standardized), 31-Dec-2025 | C40: 1192174 | D40: $mm | E40: Citi FY2025 Form 10-K | F40: Note 22 Regulatory Capital (R65.htm) | G40: https://www.sec.gov/Archives/edgar/data/831001/000083100126000011/R65.htm | H40: 2026-09-29 | I40: Regulatory | J40: Advanced Approaches RWA is not used.
A41: 40 | B41: Risk-weighted assets (Standardized), 31-Dec-2024 | C41: 1139988 | D41: $mm | E41: Citi FY2025 Form 10-K | F41: Note 22 Regulatory Capital (R65.htm) | G41: https://www.sec.gov/Archives/edgar/data/831001/000083100126000011/R65.htm | H41: 2026-09-29 | I41: Regulatory | J41: Opening RWA.
A42: 41 | B42: Dividends paid FY2025 | C42: 5372 | D42: $mm | E42: Citi FY2025 Form 10-K | F42: Consolidated Statement of Cash Flows (R9.htm), financing | G42: https://www.sec.gov/Archives/edgar/data/831001/000083100126000011/R9.htm | H42: 2026-09-29 | I42: Regulatory | J42: Common and preferred as presented in the cash-flow statement.
A43: 42 | B43: Treasury stock acquired FY2025 | C43: 13250 | D43: $mm | E43: Citi FY2025 Form 10-K | F43: Consolidated Statement of Cash Flows (R9.htm), financing | G43: https://www.sec.gov/Archives/edgar/data/831001/000083100126000011/R9.htm | H43: 2026-09-29 | I43: Regulatory | J43: Share repurchases.
A44: 43 | B44: AOCI balance, 31-Dec-2024 | C44: -47852 | D44: $mm | E44: Citi FY2025 Form 10-K | F44: Consolidated Balance Sheet (R5.htm), accumulated other comprehensive income (loss) | G44: https://www.sec.gov/Archives/edgar/data/831001/000083100126000011/R5.htm | H44: 2026-09-29 | I44: Regulatory | J44: Confirmed against primary SEC EDGAR filing: Citi FY2025 Form 10-K Consolidated Balance Sheet (Statement R5, accession 0000831001-26-000011). Represents accumulated other comprehensive income (loss).
A45: 44 | B45: AOCI balance, 31-Dec-2025 | C45: -41897 | D45: $mm | E45: Citi FY2025 Form 10-K | F45: Consolidated Balance Sheet (R5.htm), accumulated other comprehensive income (loss) | G45: https://www.sec.gov/Archives/edgar/data/831001/000083100126000011/R5.htm | H45: 2026-09-29 | I45: Regulatory | J45: Confirmed against primary SEC EDGAR filing: Citi FY2025 Form 10-K Consolidated Balance Sheet (Statement R5, accession 0000831001-26-000011). Represents accumulated other comprehensive income (loss).
A46: 45 | B46: CET1 ratio as stated in the 10-K, 31-Dec-2025 | C46: 0.132 | D46: % | E46: Citi FY2025 Form 10-K | F46: Item 7, Capital Resources: Common Equity Tier 1 Capital Ratio and SLR | G46: https://www.sec.gov/Archives/edgar/data/831001/000083100126000011/c-20251231.htm | H46: 2026-09-30 | I46: Regulatory | J46: Standardized Approach, rounded to 0.1pp. Confirmed in the 10-K text via search excerpt on 2026-09-30. Independent tie-out of CET1 / RWA.
A47: 46 | B47: CET1 headroom over requirement as stated by Citi | C47: 0.016 | D47: % | E47: Citi Q4 2025 earnings release (8-K, 2026-01-14) | F47: CEO headline: 160 basis points above regulatory requirement | G47: https://www.citigroup.com/rcs/citigpa/storage/public/Earnings/Q42025/citigroup-4q25-earnings-8-k-1-14-26.pdf | H47: 2026-09-30 | I47: Regulatory | J47: Used as an independent tie-out of the requirement stack.
A48: 47 | B48: Efficiency ratio improvement as stated by Citi, FY2025 vs FY2024 | C48: 0.017 | D48: % | E48: Citi Full-Year 2025 Results at a Glance | F48: 170 bps improvement in the efficiency ratio YoY | G48: https://www.citigroup.com/rcs/citigpa/storage/public/Earnings/Q42025/Citi-at-a-glance-full-year-2025.pdf | H48: 2026-09-30 | I48: README checks | J48: Independent tie-out of revenue and opex together.
A49: 48 | B49: Minimum CET1 requirement | C49: 0.045 | D49: % | E49: Basel III minimum | F49: Regulatory minimum | G49: n/a (Basel III minimum, not Citi-specific) | H49: 2026-09-30 | I49: Regulatory | J49: Part of the 11.6% stack.
A50: 49 | B50: Stress capital buffer (from 1-Oct-2025) | C50: 0.036 | D50: % | E50: Citi Form 8-K, 2025-07-01 (indicative SCB) | F50: Stress test announcement | G50: https://www.sec.gov/Archives/edgar/data/831001/000110465925064857/c-20250701x8k.htm | H50: 2026-09-30 | I50: Regulatory | J50: Indicative at announcement; the final notice came later in Q3. Consistent with the 10-K stated requirement of 11.6%.
A51: 50 | B51: G-SIB surcharge | C51: 0.035 | D51: % | E51: Citi FY2025 Form 10-K | F51: Item 7, Capital Resources: G-SIB Surcharge (Method 2) | G51: https://www.sec.gov/Archives/edgar/data/831001/000083100126000011/c-20251231.htm | H51: 46296 | I51: Regulatory | J51: Confirmed against primary SEC EDGAR filing: Citi FY2025 Form 10-K Item 7 (Method 2 surcharge of 3.5%, accession 0000831001-26-000011). Stack of 4.5% + 3.6% SCB + 3.5% G-SIB ties exactly to stated 11.6% requirement.
A52: 51 | B52: Required Standardized CET1 ratio as stated in the 10-K, 31-Dec-2025 | C52: 0.116 | D52: % | E52: Citi FY2025 Form 10-K | F52: Item 7, Capital Resources: Common Equity Tier 1 Capital Ratio and SLR | G52: https://www.sec.gov/Archives/edgar/data/831001/000083100126000011/c-20251231.htm | H52: 2026-09-30 | I52: Regulatory | J52: The 10-K states a required Standardized CET1 ratio of 11.6% at 31-Dec-2025. Confirmed via search excerpt on 2026-09-30. Used to test the 4.5% + SCB + G-SIB stack.

Sheet Inputs
A1: INPUTS - MODEL PARAMETERS
A2: Evidence lives in RAW_Data. The only values here are test tolerances, not data.
A4: Parameter | B4: Value | C4: Units | D4: Why
A5: CET1 tie tolerance | B5: 0.0005 | C5: fraction | D5: Citi states its CET1 ratio and headroom rounded to 0.1pp and 10bp, so ties are tested to within 5bp.
A6: Adjusted-expense tie tolerance | B6: 0.005 | C6: fraction | D6: Citi-stated adjusted expenses are rounded to $0.1B and come from a secondary summary, so the model figure is tested to within 0.5%.

Sheet OPEX_YoY
A1: OPEX_YOY - FY2024 vs FY2025 OPERATING EXPENSES BY LINE, AND UNDERLYING BASIS
A2: $mm. Positive change = expense increase. FY2024 and FY2023 are the recast comparatives in the FY2025 10-K.
B3: Line | C3: FY2024 | D3: FY2025 | E3: Change $mm | F3: Change %
B4: Compensation and benefits | C4: =RAW_Data!$C$15 -> 28542 | D4: =RAW_Data!$C$3 -> 29639 | E4: =D4-C4 -> 1097 | F4: =IF(C4<=0,"n/m",E4/C4) -> 0.038434588
B5: Technology / communication | C5: =RAW_Data!$C$16 -> 9035 | D5: =RAW_Data!$C$4 -> 9423 | E5: =D5-C5 -> 388 | F5: =IF(C5<=0,"n/m",E5/C5) -> 0.042944106
B6: Transactional and product servicing | C6: =RAW_Data!$C$17 -> 4438 | D6: =RAW_Data!$C$5 -> 4575 | E6: =D6-C6 -> 137 | F6: =IF(C6<=0,"n/m",E6/C6) -> 0.030869761
B7: Premises and equipment | C7: =RAW_Data!$C$18 -> 2438 | D7: =RAW_Data!$C$6 -> 2477 | E7: =D7-C7 -> 39 | F7: =IF(C7<=0,"n/m",E7/C7) -> 0.015996719
B8: Professional services | C8: =RAW_Data!$C$19 -> 2016 | D8: =RAW_Data!$C$7 -> 2073 | E8: =D8-C8 -> 57 | F8: =IF(C8<=0,"n/m",E8/C8) -> 0.02827381
B9: Advertising and marketing | C9: =RAW_Data!$C$20 -> 1113 | D9: =RAW_Data!$C$8 -> 1097 | E9: =D9-C9 -> -16 | F9: =IF(C9<=0,"n/m",E9/C9) -> -0.014375562
B10: Other operating | C10: =RAW_Data!$C$21 -> 5726 | D10: =RAW_Data!$C$9 -> 5862 | E10: =D10-C10 -> 136 | F10: =IF(C10<=0,"n/m",E10/C10) -> 0.02375131
B11: Restructuring | C11: =RAW_Data!$C$22 -> 259 | D11: =RAW_Data!$C$10 -> -14 | E11: =D11-C11 -> -273 | F11: =IF(C11<=0,"n/m",E11/C11) -> -1.0540541
B12: Sum of lines | C12: =SUM(C4:C11) -> 53567 | D12: =SUM(D4:D11) -> 55132
B13: Reported total operating expenses | C13: =RAW_Data!$C$23 -> 53567 | D13: =RAW_Data!$C$12 -> 55132 | E13: =D13-C13 -> 1565 | F13: =E13/C13 -> 0.029215748
B14: Check: sum of lines less reported total (must be 0) | C14: =C12-C13 -> 0 | D14: =D12-D13 -> 0
B16: Non-people lines excluding restructuring | C16: =SUM(C5:C10) -> 24766 | D16: =SUM(D5:D10) -> 25507 | E16: =D16-C16 -> 741 | F16: =E16/C16 -> 0.029920052
B17: Other operating excluding the Mexico goodwill impairment | C17: =C10 -> 5726 | D17: =D10-RAW_Data!$C$31 -> 5136 | E17: =D17-C17 -> -590 | F17: =E17/C17 -> -0.10303877
B19: UNDERLYING BASIS - excluding divestiture-related items and the FDIC special assessment
C21: FY2023 | D21: FY2024 | E21: FY2025
B22: Reported total operating expenses | C22: =RAW_Data!$C$25 -> 55970 | D22: =RAW_Data!$C$23 -> 53567 | E22: =RAW_Data!$C$12 -> 55132
B23: Less: divestiture-related operating expenses | C23: =RAW_Data!$C$33 -> 372 | D23: =RAW_Data!$C$32 -> 318 | E23: =RAW_Data!$C$30 -> 877
B24: Less: FDIC special assessment (FY2025 is a net credit) | C24: =RAW_Data!$C$36 -> 1706 | D24: =RAW_Data!$C$35 -> 203 | E24: =RAW_Data!$C$34 -> -238
B25: Underlying operating expenses | C25: =C22-C23-C24 -> 53892 | D25: =D22-D23-D24 -> 53046 | E25: =E22-E23-E24 -> 54493
B26: Change vs prior year, $mm | D26: =D25-C25 -> -846 | E26: =E25-D25 -> 1447
B27: Change vs prior year, underlying % | D27: =D25/C25-1 -> -0.015698063 | E27: =E25/D25-1 -> 0.027278211
B28: Change vs prior year, reported % | D28: =D22/C22-1 -> -0.042933714 | E28: =E22/D22-1 -> 0.029215748
B30: Memo: Mexico goodwill impairment inside FY2025 divestiture-related costs (Citi records it in Other expenses) | E30: =RAW_Data!$C$31 -> 726
B31: Memo: other FY2025 divestiture-related costs (separation, severance; line not disclosed) | E31: =E23-E30 -> 151
B33: Cross-check: Citi-stated adjusted FY2025 expenses, excluding the Banamex impairment (approx.) | E33: =RAW_Data!$C$37 -> 54400
B34: Reported less Mexico goodwill impairment, minus the Citi-stated figure | E34: =(E22-E30)-E33 -> 6
B35: Difference as % of Citi adjusted | E35: =E34/E33 -> 0.00011029412
B37: Limits: Citi places the Mexico goodwill impairment in Other expenses, but the remaining divestiture-related costs and the FDIC assessment are not placed by line, so line-level changes above include that noise. Citi's own adjusted figure removes only the impairment, which is why the cross-check uses that definition.

Sheet Variance
A1: VARIANCE - PEOPLE COST VOLUME / RATE AND TOTAL OPEX BRIDGE (FY2024 -> FY2025)
A2: $mm unless stated. Positive = unfavourable (higher cost).
C4: FY2023 | D4: FY2024 | E4: FY2025
B5: Year-end full-time employees | C5: =RAW_Data!$C$29 -> 239000 | D5: =RAW_Data!$C$28 -> 229000 | E5: =RAW_Data!$C$27 -> 226000
B6: Average employees (approx.: mean of opening and closing year-end) | D6: =(C5+D5)/2 -> 234000 | E6: =(D5+E5)/2 -> 227500
B7: Compensation and benefits, $mm | D7: =OPEX_YoY!C4 -> 28542 | E7: =OPEX_YoY!D4 -> 29639
B8: Compensation and benefits per average employee, $ | D8: =D7*1000000/D6 -> 121974.36 | E8: =E7*1000000/E6 -> 130281.32
B9: Change in average employees, % | E9: =E6/D6-1 -> -0.027777778
B10: Change in comp per average employee, % | E10: =E8/D8-1 -> 0.068104147
B11: Average employees is an approximation: Citi does not disclose quarterly headcount in the 10-K. If reductions were front-loaded in a year the true average is lower than shown; if back-loaded it is higher. Comp per head includes severance, incentive pay, FX and mix, so the rate variance is not a pure wage-inflation measure.
B13: BRIDGE 1 - PEOPLE COST (comp and benefits)
B14: FY2024 compensation and benefits | C14: =D7 -> 28542
B15: VOLUME: (FY2025 avg employees - FY2024 avg employees) x FY2024 cost per head | C15: =(E6-D6)*D8/1000000 -> -792.83333
B16: RATE: (FY2025 cost per head - FY2024 cost per head) x FY2025 avg employees | C16: =(E8-D8)*E6/1000000 -> 1889.8333
B17: FY2025 compensation and benefits (baseline + volume + rate) | C17: =SUM(C14:C16) -> 29639
B18: Check vs reported FY2025 comp and benefits (must be 0) | C18: =ROUND(C17-E7,1) -> 0 | D18: Arithmetic identity: volume and rate are defined to sum to the change, so this catches formula errors only.
B19: Scale check: severance Citi cited in Q2 2025 compensation alone, $mm | C19: =RAW_Data!$C$11 -> 400
B20: as % of the people-cost rate variance | C20: =C19/C16 -> 0.21165888 | D20: Scale indicator only: one quarter, and Citi gives no full-year figure.
B21: BRIDGE 2 - TOTAL OPERATING EXPENSES (reported basis)
B22: Step | C22: Delta $mm | D22: Cum. start | E22: Cum. end | F22: Chart base | G22: Chart height
B23: FY2024 total operating expenses | C23: - | D23: =RAW_Data!$C$23 -> 53567 | E23: =D23 -> 53567 | F23: =0 -> 0 | G23: =E23 -> 53567
B24: Headcount volume | C24: =C15 -> -792.83333 | D24: =E23 -> 53567 | E24: =D24+C24 -> 52774.167 | F24: =MIN(D24,E24) -> 52774.167 | G24: =ABS(C24) -> 792.83333
B25: Cost per head (rate) | C25: =C16 -> 1889.8333 | D25: =E24 -> 52774.167 | E25: =D25+C25 -> 54664 | F25: =MIN(D25,E25) -> 52774.167 | G25: =ABS(C25) -> 1889.8333
B26: Non-people lines ex-restructuring | C26: =OPEX_YoY!E16 -> 741 | D26: =E25 -> 54664 | E26: =D26+C26 -> 55405 | F26: =MIN(D26,E26) -> 54664 | G26: =ABS(C26) -> 741
B27: Restructuring line change | C27: =OPEX_YoY!E11 -> -273 | D27: =E26 -> 55405 | E27: =D27+C27 -> 55132 | F27: =MIN(D27,E27) -> 55132 | G27: =ABS(C27) -> 273
B28: FY2025 total operating expenses (bridge) | C28: =E27 -> 55132 | D28: - | E28: =E27 -> 55132 | F28: =0 -> 0 | G28: =E28 -> 55132
B29: Check: bridge end less reported FY2025 total (must be 0) | C29: =ROUND(C28-RAW_Data!$C$12,1) -> 0
B30: The non-people step is built line by line from OPEX_YoY, not as a residual, so this check fails if the line items do not foot to the reported totals.
B32: RECONCILIATION - reported change to underlying change
B33: Reported change in total operating expenses | C33: =RAW_Data!$C$12-RAW_Data!$C$23 -> 1565
B34: Less: change in divestiture-related costs (FY2025 less FY2024) | C34: =RAW_Data!$C$30-RAW_Data!$C$32 -> 559
B35: Less: change in FDIC special assessment (FY2025 less FY2024) | C35: =RAW_Data!$C$34-RAW_Data!$C$35 -> -441
B36: Underlying change | C36: =C33-C34-C35 -> 1447
B37: Check vs OPEX_YoY underlying change (must be 0) | C37: =ROUND(C36-OPEX_YoY!E26,1) -> 0

Sheet Regulatory
A1: REGULATORY - CET1 WALK, RATIO DRIVERS AND REQUIREMENT
A2: Capital inputs are consumed from the filings. This sheet does not compute regulatory capital.
B4: A. CET1 CAPITAL WALK ($mm)
B5: Opening CET1 (31-Dec-2024) | C5: =RAW_Data!$C$39 -> 155363
B6: Add: net income attributable to Citigroup | C6: =RAW_Data!$C$13 -> 14306
B7: Less: dividends paid | C7: =-RAW_Data!$C$42 -> -5372
B8: Less: treasury stock acquired (buybacks) | C8: =-RAW_Data!$C$43 -> -13250
B9: Subtotal | C9: =SUM(C5:C8) -> 151047 | D9: Payouts exceed net income, so capital would have fallen without other movements.
B10: Other movements (reported closing less subtotal) | C10: =C11-C9 -> 6052 | D10: The 10-K cites net beneficial AOCI movements and the Banamex stake sale and held-for-sale accounting, alongside repurchases, dividends, net income and RWA growth.
B11: Closing CET1 (31-Dec-2025, reported) | C11: =RAW_Data!$C$38 -> 157099
B12: of which: change in AOCI (balance-sheet proxy) | C12: =RAW_Data!$C$45-RAW_Data!$C$44 -> 5955 | D12: Balance-sheet AOCI per Statement R5. Serves as capital walk proxy; under Basel III Standardized Approach prudential rules, certain AOCI components (such as cash flow hedge reserves and cumulative DVA) are excluded via regulatory capital filters and adjustments.
B13: of which: remaining unexplained | C13: =C10-C12 -> 97 | D13: Not attributed.
B14: B. RATIO DRIVERS
B15: Opening RWA (Standardized) | C15: =RAW_Data!$C$41 -> 1139988
B16: Closing RWA (Standardized) | C16: =RAW_Data!$C$40 -> 1192174
B17: RWA change, $mm | C17: =C16-C15 -> 52186
B18: RWA change, % | C18: =C17/C15 -> 0.045777675
B19: CET1 capital change, $mm | C19: =C11-C5 -> 1736
B20: CET1 capital change, % | C20: =C19/C5 -> 0.011173832
B21: Opening CET1 ratio (opening CET1 / opening RWA) | C21: =C5/C15 -> 0.13628477
B22: Closing CET1 ratio (closing CET1 / closing RWA) | C22: =C11/C16 -> 0.13177523
B23: Change in ratio, pp | C23: =C22-C21 -> -0.0045095405
B24: of which: capital growth (change in CET1 / closing RWA) | C24: =(C11-C5)/C16 -> 0.0014561633
B25: of which: RWA growth (opening CET1 x change in 1/RWA) | C25: =C5*(1/C16-1/C15) -> -0.0059657037
B26: Check: drivers less total change (must be 0) | C26: =ROUND(C24+C25-C23,8) -> 0
B27: CET1 ratio stated by Citi (rounded) | C27: =RAW_Data!$C$46 -> 0.132
B28: Model closing ratio less Citi-stated | C28: =C22-C27 -> -0.00022477256
B30: C. REQUIREMENT AND HEADROOM
B31: Minimum CET1 | C31: =RAW_Data!$C$49 -> 0.045
B32: Stress capital buffer | C32: =RAW_Data!$C$50 -> 0.036
B33: G-SIB surcharge | C33: =RAW_Data!$C$51 -> 0.035
B34: Total CET1 requirement (sum) | C34: =SUM(C31:C33) -> 0.116
B35: Requirement stated by Citi | C35: =RAW_Data!$C$52 -> 0.116
B36: Headroom over requirement (closing ratio less sum), pp | C36: =C22-C34 -> 0.015775227
B37: Headroom stated by Citi | C37: =RAW_Data!$C$47 -> 0.016
B38: Model headroom less Citi-stated | C38: =C36-C37 -> -0.00022477256
B40: Method note: the G-SIB surcharge is the higher of the two methods and is 3.5% in Citi's disclosures. Citi's own stated requirement (11.6%) equals 4.5% + 3.6% + 3.5%, which the README check tests.

Sheet Dashboard
B1: CITIGROUP FY2025 | OPERATING EXPENSE AND CAPITAL DASHBOARD
B2: FY2024 vs FY2025 from the FY2025 10-K (recast comparatives). $mm unless stated. Every number on this page is a formula.
B4: THE ANSWER
B5: ="Reported operating expenses rose $"&TEXT(OPEX_YoY!E13,"#,##0")&"mm ("&TEXT(OPEX_YoY!F13,"0.0%")&"). Excluding divestiture-related items and the FDIC special assessment, they rose $"&TEXT(OPEX_YoY!E26,"#,##0")&"mm ("&TEXT(OPEX_YoY!E27,"0.0%")&") while average headcount fell about "&TEXT(-Variance!E9,"0.0%")&". Comp and benefits rose $"&TEXT(OPEX_YoY!E4,"#,##0")&"mm, and the $"&TEXT(RAW_Data!$C$31,"#,##0")&"mm Mexico goodwill impairment, which Citi records in Other expenses, explains "&TEXT(RAW_Data!$C$31/OPEX_YoY!E16,"0%")&" of the $"&TEXT(OPEX_YoY!E16,"#,##0")&"mm rise in non-people lines." -> Reported operating expenses rose $1,565mm (2.9%). Excluding divestiture-related items and the FDIC special assessment, they rose $1,447mm (2.7%) while average headcount fell about 2.8%. Comp and benefits rose $1,097mm, and the $726mm Mexico goodwill impairment, which Citi records in Other expenses, explains 98% of the $741mm rise in non-people lines.
B7: KEY NUMBERS
B8: Metric | C8: FY2024 | D8: FY2025 | E8: Change | F8: Change %
B9: Reported operating expenses | C9: =OPEX_YoY!C13 -> 53567 | D9: =OPEX_YoY!D13 -> 55132 | E9: =D9-C9 -> 1565 | F9: =D9/C9-1 -> 0.029215748
B10: Underlying opex (ex divestiture items, ex FDIC) | C10: =OPEX_YoY!D25 -> 53046 | D10: =OPEX_YoY!E25 -> 54493 | E10: =D10-C10 -> 1447 | F10: =D10/C10-1 -> 0.027278211
B11: Total revenues | C11: =RAW_Data!$C$14 -> 80722 | D11: =RAW_Data!$C$2 -> 85225 | E11: =D11-C11 -> 4503 | F11: =D11/C11-1 -> 0.055784049
B12: Efficiency ratio (reported opex / revenue) | C12: =C9/C11 -> 0.66359852 | D12: =D9/D11 -> 0.64689938 | E12: =D12-C12 -> -0.016699139
B13: Year-end employees | C13: =Variance!D5 -> 229000 | D13: =Variance!E5 -> 226000 | E13: =D13-C13 -> -3000 | F13: =D13/C13-1 -> -0.013100437
B14: Average employees (approx.) | C14: =Variance!D6 -> 234000 | D14: =Variance!E6 -> 227500 | E14: =D14-C14 -> -6500 | F14: =D14/C14-1 -> -0.027777778
B15: Comp and benefits per average employee ($) | C15: =Variance!D8 -> 121974.36 | D15: =Variance!E8 -> 130281.32 | E15: =D15-C15 -> 8306.9597 | F15: =D15/C15-1 -> 0.068104147
B16: CET1 ratio | C16: =Regulatory!C21 -> 0.13628477 | D16: =Regulatory!C22 -> 0.13177523 | E16: =D16-C16 -> -0.0045095405
B17: ="CET1 headroom over "&TEXT(Regulatory!C34,"0.0%")&" requirement (pp)" -> CET1 headroom over 11.6% requirement (pp) | D17: =Regulatory!C36 -> 0.015775227
B19: BRIDGE - FY2024 TO FY2025 (reported basis)
B20: Step | C20: $mm | D20: What it means
B21: FY2024 total operating expenses | C21: =Variance!D23 -> 53567 | D21: ="Recast comparative from the FY2025 10-K." -> Recast comparative from the FY2025 10-K.
B22: Headcount volume | C22: =Variance!C24 -> -792.83333 | D22: ="Average employees fell from "&TEXT(Variance!D6,"#,##0")&" to "&TEXT(Variance!E6,"#,##0")&" (mean of year-end figures), a saving of $"&TEXT(ABS(Variance!C15),"#,##0")&"mm at FY2024 cost per head." -> Average employees fell from 234,000 to 227,500 (mean of year-end figures), a saving of $793mm at FY2024 cost per head.
B23: Cost per head (rate) | C23: =Variance!C25 -> 1889.8333 | D23: ="Comp per average employee rose from $"&TEXT(Variance!D8,"#,##0")&" to $"&TEXT(Variance!E8,"#,##0")&" ("&TEXT(Variance!E10,"0.0%")&"). This includes severance, FX and mix, so it is not a pure wage measure." -> Comp per average employee rose from $121,974 to $130,281 (6.8%). This includes severance, FX and mix, so it is not a pure wage measure.
B24: Non-people lines ex-restructuring | C24: =Variance!C26 -> 741 | D24: ="Six non-people lines rose $"&TEXT(OPEX_YoY!E16,"#,##0")&"mm. That includes the $"&TEXT(RAW_Data!$C$31,"#,##0")&"mm Mexico goodwill impairment, which Citi records in Other expenses. Without it those lines rose $"&TEXT(OPEX_YoY!E16-RAW_Data!$C$31,"#,##0")&"mm." -> Six non-people lines rose $741mm. That includes the $726mm Mexico goodwill impairment, which Citi records in Other expenses. Without it those lines rose $15mm.
B25: Restructuring line change | C25: =Variance!C27 -> -273 | D25: ="Restructuring moved from a $"&TEXT(OPEX_YoY!C11,"#,##0")&"mm charge to a $"&TEXT(ABS(OPEX_YoY!D11),"#,##0")&"mm credit. It is not all of severance: part is booked inside comp and benefits." -> Restructuring moved from a $259mm charge to a $14mm credit. It is not all of severance: part is booked inside comp and benefits.
B26: FY2025 total operating expenses | C26: =Variance!C28 -> 55132 | D26: ="Bridge check vs reported: "&TEXT(Variance!C29,"0.0")&" (fails if the line items do not foot)." -> Bridge check vs reported: 0.0 (fails if the line items do not foot).
B28: THREE YEARS - WHAT ONE YEAR HIDES
B29: Metric | C29: FY2023 | D29: FY2024 | E29: FY2025
B30: Reported operating expenses | C30: =OPEX_YoY!C22 -> 55970 | D30: =OPEX_YoY!D22 -> 53567 | E30: =OPEX_YoY!E22 -> 55132
B31: change vs prior year | D31: =OPEX_YoY!D28 -> -0.042933714 | E31: =OPEX_YoY!E28 -> 0.029215748
B32: Underlying operating expenses | C32: =OPEX_YoY!C25 -> 53892 | D32: =OPEX_YoY!D25 -> 53046 | E32: =OPEX_YoY!E25 -> 54493
B33: change vs prior year | D33: =OPEX_YoY!D27 -> -0.015698063 | E33: =OPEX_YoY!E27 -> 0.027278211
B34: Efficiency ratio (reported) | C34: =RAW_Data!$C$25/RAW_Data!$C$24 -> 0.71695745 | D34: =RAW_Data!$C$23/RAW_Data!$C$14 -> 0.66359852 | E34: =RAW_Data!$C$12/RAW_Data!$C$2 -> 0.64689938
B35: Year-end employees | C35: =Variance!C5 -> 239000 | D35: =Variance!D5 -> 229000 | E35: =Variance!E5 -> 226000
B36: Restructuring charge / (credit) | C36: =RAW_Data!$C$26 -> 781 | D36: =RAW_Data!$C$22 -> 259 | E36: =RAW_Data!$C$10 -> -14
B37: ="Reported expenses moved "&TEXT(OPEX_YoY!D28,"0.0%;-0.0%")&" in FY2024 and "&TEXT(OPEX_YoY!E28,"0.0%;-0.0%")&" in FY2025. On the underlying basis the moves were "&TEXT(OPEX_YoY!D27,"0.0%;-0.0%")&" and "&TEXT(OPEX_YoY!E27,"0.0%;-0.0%")&". The roll-off of the FDIC special assessment explains "&TEXT((RAW_Data!$C$36-RAW_Data!$C$35)/(RAW_Data!$C$25-RAW_Data!$C$23),"0%")&" of the FY2024 reported decline." -> Reported expenses moved -4.3% in FY2024 and 2.9% in FY2025. On the underlying basis the moves were -1.6% and 2.7%. The roll-off of the FDIC special assessment explains 63% of the FY2024 reported decline.
B39: WHAT THE DATA SUPPORTS
B40: - Expenses rose on both the reported and the underlying basis even though average headcount fell.
B41: - Comp per head rose by more than headcount fell, so people cost increased. The rate effect is larger than the volume effect.
B42: - The CET1 ratio fell because RWA grew faster than CET1 capital. Payouts exceeded net income, and capital still rose only because AOCI and other items added more (see Regulatory).
B43: - Excluding the Mexico goodwill impairment, compensation and benefits rose by more than total expenses did, so non-people lines were roughly flat.
B44: WHAT THE DATA DOES NOT SUPPORT
B45: - Whether Citi met its restructuring savings plan. The plan runs to end-2026 and quotes run-rate savings, which annual 10-K lines cannot isolate.
...
